<mujoco model="snake3">
	<compiler inertiafromgeom="true" angle="radian"/>
	<default>
		<joint limited="true" range="-1.5 1.5"/>
		<motor ctrllimited="true" ctrlrange="-5 5"/>
		<default class="body">
			<geom contype="1" conaffinity="1" material="matbody"/>
		</default>
	</default>
	<option timestep="0.01"  integrator="RK4"/>
	
	<asset>
		<texture type="skybox" builtin="gradient" rgb1="0.3 0.5 0.7" rgb2=".1 .15 .2" width="512" height="512"/>
		<texture name="texplane" type="2d" builtin="checker" rgb1=".2 .3 .4" rgb2=".1 .15 .2" width="512" height="512" mark="cross" markrgb=".8 .8 .8" />
		<material name="matplane" reflectance="0.3" texture="texplane" texrepeat="1 1" texuniform="true" />
		<material name="matbody" specular="3" shininess=".5" reflectance="1" rgba=".3 .4 .35 1" />
	</asset>
	
	<sensor>
		<velocimeter name="head_velocity" site="head"/>
		<velocimeter name="velocity1" site="bsensor1"/>
		<velocimeter name="velocity2" site="bsensor2"/>
		<velocimeter name="velocity3" site="bsensor3"/>
		<velocimeter name="velocity4" site="bsensor4"/>
		<velocimeter name="velocity5" site="bsensor5"/>
		<velocimeter name="velocity6" site="bsensor6"/>
		
	</sensor>
	
	

	<worldbody>
		<light directional="true" cutoff="100" exponent="1" diffuse="1 1 1" specular=".1 .1 .1" pos="0 0 1.3" dir="-0 0 -1.3"/>
		<geom name="ground" material="matplane" type="plane" pos="0 0 0" size="30 30 1" contype="0" conaffinity="0" rgba="0.25 0.64 0.85 .2" condim="6"  />
		<geom name="target_marker" type="sphere" size="0.02"  rgba="1 1 0 1" pos="0.0 0.0 0" contype="0" conaffinity="0"/>
		
		<body name="sn1" pos="-1.2 0.0 0.02" childclass="body">
			<site name="eyeL" type="sphere" size="0.005" pos=".01 -.01 .01" rgba=".9 .4 .2 1"/>
			<site name="eyeR" type="sphere" size="0.005" pos=".01 0.01 .01" rgba=".9 .4 .2 1"/>
			<site name="head" material="matplane" type="sphere" size="0.02" pos="0 0 0" rgba="0 0 0 1"/>
			<site name="bsensor1" material="matplane" type="sphere" size="0.01" pos="-0.04 0 0.02" rgba="1 1 1 1"/>

			<inertial pos="-0.04 0 0" quat="0.707 0 -0.707 0" mass="0.1" diaginertia="0.016 0.0016 0.0001"/>
			<joint name="h1" type="slide" pos="0 0 0.02" axis="1 0 0" limited="false"/>
			<joint name="h2" type="slide" pos="0 0 0.02" axis="0 1 0" limited="false"/>
			<joint name="h3" type="hinge" pos="0 0 0.02" axis="0 0 1" limited="false"/>
			<geom name="snake1" type="box" pos="-0.04 0 0" quat="0.707 0 -0.707 0" size="0.02 0.02 0.04" />
			
			<body name="x1" pos ="-0.1 0 0">
				<joint name="j1" type="hinge" pos="0 0 0" axis="0 0 1"/>
				<geom type="sphere" size="0.02"/>
				
				<body name="sn2" pos="-0.02 0 0">
					<inertial pos="-0.03 0 0" quat="0.707 0 -0.707 0" mass="0.1" diaginertia="0.0016 0.0016 0.0001"/>
					<geom name="snake2" type="box" pos="-0.03 0 0" quat="0.707 0 -0.707 0" size="0.02 0.02 0.03" />
					<site name="bsensor2" material="matplane" type="sphere" size="0.01" pos="-0.03 0 0.02" rgba="1 1 1 1"/>
					
					<body name="x2" pos ="-0.08 0 0">
						<joint name="j2" type="hinge" pos="0 0 0" axis="0 0 1"/>
						<geom type="sphere" size="0.02"/>
					
					
						<body name="sn3" pos="-0.02 0 0">
							<inertial pos="-0.03 0 0" quat="0.707 0 -0.707 0" mass="0.1" diaginertia="0.0016 0.0016 0.0001"/>
							<geom name="snake3" type="box" pos="-0.03 0 0" quat="0.707 0 -0.707 0" size="0.02 0.02 0.03" />
							<site name="bsensor3" material="matplane" type="sphere" size="0.01" pos="-0.03 0 0.02" rgba="1 1 1 1"/>
						
							<body name="x3" pos ="-0.08 0 0">
								<joint name="j3" type="hinge" pos="0 0 0" axis="0 0 1"/>
								<geom type="sphere" size="0.02"/>
								
								
						
								<body name="sn4" pos="-0.02 0 0">
									<inertial pos="-0.03 0 0" quat="0.707 0 -0.707 0" mass="0.1" diaginertia="0.0016 0.0016 0.0001"/>
									<geom name="snake4" type="box" pos="-0.03 0 0" quat="0.707 0 -0.707 0" size="0.02 0.02 0.03" />
									<site name="bsensor4" material="matplane" type="sphere" size="0.01" pos="-0.03 0 0.02" rgba="1 1 1 1"/>
									
									<body name="x4" pos ="-0.08 0 0">
										<joint name="j4" type="hinge" pos="0 0 0" axis="0 0 1"/>
										<geom type="sphere" size="0.02"/>
									
									
										<body name="sn5" pos="-0.02 0 0">
											<inertial pos="-0.03 0 0" quat="0.707 0 -0.707 0" mass="0.1" diaginertia="0.0016 0.0016 0.0001"/>
											<geom name="snake5" type="box" pos="-0.03 0 0" quat="0.707 0 -0.707 0" size="0.02 0.02 0.03" />
											<site name="bsensor5" material="matplane" type="sphere" size="0.01" pos="-0.03 0 0.02" rgba="1 1 1 1"/>
											
											<body name="x5" pos ="-0.08 0 0">
												<joint name="j5" type="hinge" pos="0 0 0" axis="0 0 1" range="-0.5 0.5"/>
												<geom type="sphere" size="0.02"/>										
											
											
												<body name="sn6" pos="-0.02 0 0">
													<inertial pos="-0.04 0 0" quat="0.707 0 -0.707 0" mass="0.1" diaginertia="0.0016 0.0016 0.0001"/>
													<geom name="snake6" type="box" pos="-0.04 0 0" quat="0.707 0 -0.707 0" size="0.02 0.02 0.04" />
													<site name="bsensor6" material="matplane" type="sphere" size="0.01" pos="-0.04 0 0.02" rgba="1 1 1 1"/>

												</body>
											</body>
										</body>
									</body>
								</body>
							</body>
						</body>
					</body>
				</body>
			</body>
		</body>
		
	
	
	</worldbody>
	
	<actuator>
		<motor joint="j1" gear="5"/>
		<motor joint="j2" gear="5"/>
		<motor joint="j3" gear="5"/>
		<motor joint="j4" gear="5"/>
		<motor joint="j5" gear="5"/>
	</actuator>
	
	<contact>
		<pair geom1="ground" geom2="snake1" condim="3" friction="5.0 5.0" />
		<pair geom1="ground" geom2="snake2" condim="3" friction="5.0 5.0" />
		<pair geom1="ground" geom2="snake3" condim="3" friction="5.0 5.0" />
		<pair geom1="ground" geom2="snake4" condim="3" friction="5.0 5.0" />
		<pair geom1="ground" geom2="snake5" condim="3" friction="5.0 5.0" />
		<pair geom1="ground" geom2="snake6" condim="3" friction="5.0 5.0" />
	</contact>
	
	
</mujoco>		
		
		
		
		
	
